Traceback (most recent call last):
  File "/Users/deepak/opt/anaconda3/envs/sparkbook/lib/python3.8/site-packages/jupyter_cache/executors/utils.py", line 51, in single_nb_execution
    executenb(
  File "/Users/deepak/opt/anaconda3/envs/sparkbook/lib/python3.8/site-packages/nbclient/client.py", line 1087, in execute
    return NotebookClient(nb=nb, resources=resources, km=km, **kwargs).execute()
  File "/Users/deepak/opt/anaconda3/envs/sparkbook/lib/python3.8/site-packages/nbclient/util.py", line 74, in wrapped
    return just_run(coro(*args, **kwargs))
  File "/Users/deepak/opt/anaconda3/envs/sparkbook/lib/python3.8/site-packages/nbclient/util.py", line 53, in just_run
    return loop.run_until_complete(coro)
  File "/Users/deepak/opt/anaconda3/envs/sparkbook/lib/python3.8/asyncio/base_events.py", line 616, in run_until_complete
    return future.result()
  File "/Users/deepak/opt/anaconda3/envs/sparkbook/lib/python3.8/site-packages/nbclient/client.py", line 540, in async_execute
    await self.async_execute_cell(
  File "/Users/deepak/opt/anaconda3/envs/sparkbook/lib/python3.8/site-packages/nbclient/client.py", line 832, in async_execute_cell
    self._check_raise_for_error(cell, exec_reply)
  File "/Users/deepak/opt/anaconda3/envs/sparkbook/lib/python3.8/site-packages/nbclient/client.py", line 740, in _check_raise_for_error
    raise CellExecutionError.from_cell_and_msg(cell, exec_reply['content'])
nbclient.exceptions.CellExecutionError: An error occurred while executing the following cell:
------------------
from pyspark.sql.functions import map_keys
df_keys = df2.select(map_keys(df2.data).alias("keys"))
df_keys.show()
------------------

[0;31m---------------------------------------------------------------------------[0m
[0;31mNameError[0m                                 Traceback (most recent call last)
[0;32m<ipython-input-10-4bf71e552607>[0m in [0;36m<module>[0;34m[0m
[1;32m      1[0m [0;32mfrom[0m [0mpyspark[0m[0;34m.[0m[0msql[0m[0;34m.[0m[0mfunctions[0m [0;32mimport[0m [0mmap_keys[0m[0;34m[0m[0;34m[0m[0m
[0;32m----> 2[0;31m [0mdf_keys[0m [0;34m=[0m [0mdf2[0m[0;34m.[0m[0mselect[0m[0;34m([0m[0mmap_keys[0m[0;34m([0m[0mdf2[0m[0;34m.[0m[0mdata[0m[0;34m)[0m[0;34m.[0m[0malias[0m[0;34m([0m[0;34m"keys"[0m[0;34m)[0m[0;34m)[0m[0;34m[0m[0;34m[0m[0m
[0m[1;32m      3[0m [0mdf_keys[0m[0;34m.[0m[0mshow[0m[0;34m([0m[0;34m)[0m[0;34m[0m[0;34m[0m[0m

[0;31mNameError[0m: name 'df2' is not defined
NameError: name 'df2' is not defined

